Workbook

Sheet Dashboard
B2: NICOBAR DESIGN PVT. LTD. · PURCHASE INVOICES FY 2026-27
B3: Expense Ledger – Dashboard | H3: As of | I3: =TODAY() -> 46298
B4: Live from the "Invoice Register" sheet – updates automatically when rows are added. Blue text = edit if needed.
B6: Invoice total | C6: Net payable (after TDS) | G6: GST charged (ITC) | H6: TDS to deduct | J6: RCM IGST payable
B7: =SUMIFS('Invoice Register'!$X$5:$X$2024,'Invoice Register'!$A$5:$A$2024,">0") -> 9266045.6 | C7: =SUMIFS('Invoice Register'!$Z$5:$Z$2024,'Invoice Register'!$A$5:$A$2024,">0") -> 8975814.6 | G7: =SUMIFS('Invoice Register'!$T$5:$T$2024,'Invoice Register'!$A$5:$A$2024,">0")+SUMIFS('Invoice Register'!$U$5:$U$2024,'Invoice Register'!$A$5:$A$2024,">0")+SUMIFS('Invoice Register'!$V$5:$V$2024,'Invoice Register'!$A$5:$A$2024,">0") -> 1115384.1 | H7: =SUMIFS('Invoice Register'!$Y$5:$Y$2024,'Invoice Register'!$A$5:$A$2024,">0") -> 290231 | J7: =ROUND(SUMIFS('Invoice Register'!$Q$5:$Q$2024,'Invoice Register'!$A$5:$A$2024,">0",'Invoice Register'!$AR$5:$AR$2024,"RCM*")*18%,0) -> 14100
B8: =SUMPRODUCT(('Invoice Register'!$C$5:$C$2024<>"")/COUNTIF('Invoice Register'!$C$5:$C$2024,'Invoice Register'!$C$5:$C$2024&"")) -> 72 | C8: =COUNTIFS('Invoice Register'!$A$5:$A$2024,">0") -> 117 | G8: Subject to GSTR-2B | H8: Confirm rates with CA | J8: 18% on import of services
B10: Spend by vendor | G10: Spend by invoice month
B11: Vendor (as in Supplier column) | C11: Invoice total | D11: Lines | E11: Share | G11: Month | H11: Invoice total | I11: Lines | J11: ₹ lakh
B12: Cushman & Wakefield India Private Limited | C12: =SUMIFS('Invoice Register'!$X$5:$X$2024,'Invoice Register'!$G$5:$G$2024,B12,'Invoice Register'!$A$5:$A$2024,">0") -> 1563500 | D12: =COUNTIFS('Invoice Register'!$G$5:$G$2024,B12,'Invoice Register'!$A$5:$A$2024,">0") -> 1 | E12: =IF($C$7=0,0,C12/$C$20) -> 0.16873433 | G12: 46113 | H12: =SUMIFS('Invoice Register'!$X$5:$X$2024,'Invoice Register'!$D$5:$D$2024,">="&G12,'Invoice Register'!$D$5:$D$2024,"<"&EDATE(G12,1),'Invoice Register'!$A$5:$A$2024,">0") -> 9383.51 | I12: =COUNTIFS('Invoice Register'!$D$5:$D$2024,">="&G12,'Invoice Register'!$D$5:$D$2024,"<"&EDATE(G12,1),'Invoice Register'!$A$5:$A$2024,">0") -> 2 | J12: =ROUND(H12/100000,2) -> 0.09
B13: DLF Home Developers Limited | C13: =SUMIFS('Invoice Register'!$X$5:$X$2024,'Invoice Register'!$G$5:$G$2024,B13,'Invoice Register'!$A$5:$A$2024,">0") -> 1482156.2 | D13: =COUNTIFS('Invoice Register'!$G$5:$G$2024,B13,'Invoice Register'!$A$5:$A$2024,">0") -> 14 | E13: =IF($C$7=0,0,C13/$C$20) -> 0.15995564 | G13: 46143 | H13: =SUMIFS('Invoice Register'!$X$5:$X$2024,'Invoice Register'!$D$5:$D$2024,">="&G13,'Invoice Register'!$D$5:$D$2024,"<"&EDATE(G13,1),'Invoice Register'!$A$5:$A$2024,">0") -> 583977.33 | I13: =COUNTIFS('Invoice Register'!$D$5:$D$2024,">="&G13,'Invoice Register'!$D$5:$D$2024,"<"&EDATE(G13,1),'Invoice Register'!$A$5:$A$2024,">0") -> 5 | J13: =ROUND(H13/100000,2) -> 5.84
B14: Antya Web Private Limited | C14: =SUMIFS('Invoice Register'!$X$5:$X$2024,'Invoice Register'!$G$5:$G$2024,B14,'Invoice Register'!$A$5:$A$2024,">0") -> 1416000 | D14: =COUNTIFS('Invoice Register'!$G$5:$G$2024,B14,'Invoice Register'!$A$5:$A$2024,">0") -> 1 | E14: =IF($C$7=0,0,C14/$C$20) -> 0.152816 | G14: 46174 | H14: =SUMIFS('Invoice Register'!$X$5:$X$2024,'Invoice Register'!$D$5:$D$2024,">="&G14,'Invoice Register'!$D$5:$D$2024,"<"&EDATE(G14,1),'Invoice Register'!$A$5:$A$2024,">0") -> 74288.08 | I14: =COUNTIFS('Invoice Register'!$D$5:$D$2024,">="&G14,'Invoice Register'!$D$5:$D$2024,"<"&EDATE(G14,1),'Invoice Register'!$A$5:$A$2024,">0") -> 3 | J14: =ROUND(H14/100000,2) -> 0.74
B15: M/s Stitch-9 | C15: =SUMIFS('Invoice Register'!$X$5:$X$2024,'Invoice Register'!$G$5:$G$2024,B15,'Invoice Register'!$A$5:$A$2024,">0") -> 1180590 | D15: =COUNTIFS('Invoice Register'!$G$5:$G$2024,B15,'Invoice Register'!$A$5:$A$2024,">0") -> 1 | E15: =IF($C$7=0,0,C15/$C$20) -> 0.12741034 | G15: 46204 | H15: =SUMIFS('Invoice Register'!$X$5:$X$2024,'Invoice Register'!$D$5:$D$2024,">="&G15,'Invoice Register'!$D$5:$D$2024,"<"&EDATE(G15,1),'Invoice Register'!$A$5:$A$2024,">0") -> 511872.28 | I15: =COUNTIFS('Invoice Register'!$D$5:$D$2024,">="&G15,'Invoice Register'!$D$5:$D$2024,"<"&EDATE(G15,1),'Invoice Register'!$A$5:$A$2024,">0") -> 6 | J15: =ROUND(H15/100000,2) -> 5.12
B16: Branch of Quang Vinh Ceramic Co., Ltd (Vietnam) | C16: =SUMIFS('Invoice Register'!$X$5:$X$2024,'Invoice Register'!$G$5:$G$2024,B16,'Invoice Register'!$A$5:$A$2024,">0") -> 1164340.8 | D16: =COUNTIFS('Invoice Register'!$G$5:$G$2024,B16,'Invoice Register'!$A$5:$A$2024,">0") -> 10 | E16: =IF($C$7=0,0,C16/$C$20) -> 0.12565671 | G16: 46235 | H16: =SUMIFS('Invoice Register'!$X$5:$X$2024,'Invoice Register'!$D$5:$D$2024,">="&G16,'Invoice Register'!$D$5:$D$2024,"<"&EDATE(G16,1),'Invoice Register'!$A$5:$A$2024,">0") -> 1308684.1 | I16: =COUNTIFS('Invoice Register'!$D$5:$D$2024,">="&G16,'Invoice Register'!$D$5:$D$2024,"<"&EDATE(G16,1),'Invoice Register'!$A$5:$A$2024,">0") -> 33 | J16: =ROUND(H16/100000,2) -> 13.09
B17: Clay Craft India Limited | C17: =SUMIFS('Invoice Register'!$X$5:$X$2024,'Invoice Register'!$G$5:$G$2024,B17,'Invoice Register'!$A$5:$A$2024,">0") -> 632596 | D17: =COUNTIFS('Invoice Register'!$G$5:$G$2024,B17,'Invoice Register'!$A$5:$A$2024,">0") -> 3 | E17: =IF($C$7=0,0,C17/$C$20) -> 0.068270331 | G17: 46266 | H17: =SUMIFS('Invoice Register'!$X$5:$X$2024,'Invoice Register'!$D$5:$D$2024,">="&G17,'Invoice Register'!$D$5:$D$2024,"<"&EDATE(G17,1),'Invoice Register'!$A$5:$A$2024,">0") -> 6588916.4 | I17: =COUNTIFS('Invoice Register'!$D$5:$D$2024,">="&G17,'Invoice Register'!$D$5:$D$2024,"<"&EDATE(G17,1),'Invoice Register'!$A$5:$A$2024,">0") -> 66 | J17: =ROUND(H17/100000,2) -> 65.89
B18: Jatin Gulabrai Parekh | C18: =SUMIFS('Invoice Register'!$X$5:$X$2024,'Invoice Register'!$G$5:$G$2024,B18,'Invoice Register'!$A$5:$A$2024,">0") -> 451443 | D18: =COUNTIFS('Invoice Register'!$G$5:$G$2024,B18,'Invoice Register'!$A$5:$A$2024,">0") -> 1 | E18: =IF($C$7=0,0,C18/$C$20) -> 0.048720136 | G18: 46296 | H18: =SUMIFS('Invoice Register'!$X$5:$X$2024,'Invoice Register'!$D$5:$D$2024,">="&G18,'Invoice Register'!$D$5:$D$2024,"<"&EDATE(G18,1),'Invoice Register'!$A$5:$A$2024,">0") -> 181844 | I18: =COUNTIFS('Invoice Register'!$D$5:$D$2024,">="&G18,'Invoice Register'!$D$5:$D$2024,"<"&EDATE(G18,1),'Invoice Register'!$A$5:$A$2024,">0") -> 1 | J18: =ROUND(H18/100000,2) -> 1.82
B19: Other / new vendors | C19: =B7-SUM(C12:C18) -> 1375419.6 | D19: =C8-SUM(D12:D18) -> 86 | E19: =IF(C20=0,0,C19/C20) -> 0.14843652 | G19: 46327 | H19: =SUMIFS('Invoice Register'!$X$5:$X$2024,'Invoice Register'!$D$5:$D$2024,">="&G19,'Invoice Register'!$D$5:$D$2024,"<"&EDATE(G19,1),'Invoice Register'!$A$5:$A$2024,">0") -> 0 | I19: =COUNTIFS('Invoice Register'!$D$5:$D$2024,">="&G19,'Invoice Register'!$D$5:$D$2024,"<"&EDATE(G19,1),'Invoice Register'!$A$5:$A$2024,">0") -> 0 | J19: =ROUND(H19/100000,2) -> 0
B20: Total | C20: =SUM(C12:C19) -> 9266045.6 | D20: =SUM(D12:D19) -> 117 | E20: =SUM(E12:E19) -> 1 | G20: 46357 | H20: =SUMIFS('Invoice Register'!$X$5:$X$2024,'Invoice Register'!$D$5:$D$2024,">="&G20,'Invoice Register'!$D$5:$D$2024,"<"&EDATE(G20,1),'Invoice Register'!$A$5:$A$2024,">0") -> 0 | I20: =COUNTIFS('Invoice Register'!$D$5:$D$2024,">="&G20,'Invoice Register'!$D$5:$D$2024,"<"&EDATE(G20,1),'Invoice Register'!$A$5:$A$2024,">0") -> 0 | J20: =ROUND(H20/100000,2) -> 0
B21: Top 7 vendors by spend (the routine refreshes this list). All others are in "Other / new vendors". | G21: 46388 | H21: =SUMIFS('Invoice Register'!$X$5:$X$2024,'Invoice Register'!$D$5:$D$2024,">="&G21,'Invoice Register'!$D$5:$D$2024,"<"&EDATE(G21,1),'Invoice Register'!$A$5:$A$2024,">0") -> 0 | I21: =COUNTIFS('Invoice Register'!$D$5:$D$2024,">="&G21,'Invoice Register'!$D$5:$D$2024,"<"&EDATE(G21,1),'Invoice Register'!$A$5:$A$2024,">0") -> 0 | J21: =ROUND(H21/100000,2) -> 0
G22: 46419 | H22: =SUMIFS('Invoice Register'!$X$5:$X$2024,'Invoice Register'!$D$5:$D$2024,">="&G22,'Invoice Register'!$D$5:$D$2024,"<"&EDATE(G22,1),'Invoice Register'!$A$5:$A$2024,">0") -> 0 | I22: =COUNTIFS('Invoice Register'!$D$5:$D$2024,">="&G22,'Invoice Register'!$D$5:$D$2024,"<"&EDATE(G22,1),'Invoice Register'!$A$5:$A$2024,">0") -> 0 | J22: =ROUND(H22/100000,2) -> 0
G23: 46447 | H23: =SUMIFS('Invoice Register'!$X$5:$X$2024,'Invoice Register'!$D$5:$D$2024,">="&G23,'Invoice Register'!$D$5:$D$2024,"<"&EDATE(G23,1),'Invoice Register'!$A$5:$A$2024,">0") -> 0 | I23: =COUNTIFS('Invoice Register'!$D$5:$D$2024,">="&G23,'Invoice Register'!$D$5:$D$2024,"<"&EDATE(G23,1),'Invoice Register'!$A$5:$A$2024,">0") -> 0 | J23: =ROUND(H23/100000,2) -> 0
G24: FY total | H24: =SUM(H12:H23) -> 9258965.6 | I24: =SUM(I12:I23) -> 116 | J24: =SUM(J12:J23) -> 92.59
G25: Before Apr-26 (prior FY) | H25: =B7-H24 -> 7080 | I25: =C8-I24 -> 1 | J25: =ROUND(H25/100000,2) -> 0.07
B27: Taxable value by GST treatment | G27: GST & TDS summary
B28: GST treatment | C28: Taxable value | D28: Lines | E28: Share | G28: Item | H28: Amount
B29: IGST | C29: =SUMIFS('Invoice Register'!$Q$5:$Q$2024,'Invoice Register'!$S$5:$S$2024,B29,'Invoice Register'!$A$5:$A$2024,">0") -> 2871602.6 | D29: =COUNTIFS('Invoice Register'!$S$5:$S$2024,B29,'Invoice Register'!$A$5:$A$2024,">0") -> 26 | E29: =IF($C$34=0,0,C29/$C$34) -> 0.35231533 | G29: IGST charged | H29: =SUMIFS('Invoice Register'!$T$5:$T$2024,'Invoice Register'!$A$5:$A$2024,">0") -> 438567.11
B30: CGST+SGST | C30: =SUMIFS('Invoice Register'!$Q$5:$Q$2024,'Invoice Register'!$S$5:$S$2024,B30,'Invoice Register'!$A$5:$A$2024,">0") -> 3802585.5 | D30: =COUNTIFS('Invoice Register'!$S$5:$S$2024,B30,'Invoice Register'!$A$5:$A$2024,">0") -> 60 | E30: =IF($C$34=0,0,C30/$C$34) -> 0.4665371 | G30: CGST charged | H30: =SUMIFS('Invoice Register'!$U$5:$U$2024,'Invoice Register'!$A$5:$A$2024,">0") -> 338408.52
B31: Import (no GST) | C31: =SUMIFS('Invoice Register'!$Q$5:$Q$2024,'Invoice Register'!$S$5:$S$2024,B31,'Invoice Register'!$A$5:$A$2024,">0") -> 1242671.8 | D31: =COUNTIFS('Invoice Register'!$S$5:$S$2024,B31,'Invoice Register'!$A$5:$A$2024,">0") -> 19 | E31: =IF($C$34=0,0,C31/$C$34) -> 0.15246272 | G31: SGST charged | H31: =SUMIFS('Invoice Register'!$V$5:$V$2024,'Invoice Register'!$A$5:$A$2024,">0") -> 338408.52
B32: No GST (unregistered) | C32: =SUMIFS('Invoice Register'!$Q$5:$Q$2024,'Invoice Register'!$S$5:$S$2024,B32,'Invoice Register'!$A$5:$A$2024,">0") -> 88000 | D32: =COUNTIFS('Invoice Register'!$S$5:$S$2024,B32,'Invoice Register'!$A$5:$A$2024,">0") -> 3 | E32: =IF($C$34=0,0,C32/$C$34) -> 0.010796671 | G32: Total GST (ITC) | H32: =SUM(H29:H31) -> 1115384.1
B33: Other | C33: =SUMIFS('Invoice Register'!$Q$5:$Q$2024,'Invoice Register'!$A$5:$A$2024,">0")-SUM(C29:C32) -> 145800.52 | D33: =C8-SUM(D29:D32) -> 9 | E33: =IF($C$34=0,0,C33/$C$34) -> 0.017888185 | G33: IGST payable under RCM | H33: =J7 -> 14100
B34: Total | C34: =SUM(C29:C33) -> 8150660.5 | D34: =SUM(D29:D33) -> 117 | E34: =SUM(E29:E33) -> 1 | G34: TDS to deduct | H34: =H7 -> 290231
G35: Net payable to vendors | H35: =C7 -> 8975814.6
G37: Check: vendor total = invoice total | H37: =IF(ABS(C20-B7)<1,"OK","MISMATCH") -> OK
B38: Charts
B57: Needs attention (as of 03-Oct-2026 – edit or clear when done)
B58: ACTION | C58: Attach the Gmail connector to the scheduled task "Auto-add new invoices to Expense Register" (daily 09:07 IST) – runs of 02 and 03 Oct could not read invoice@nicobar.com.
B59: ACTION | C59: 4 large emails (24–25 Sep, 12–28 MB) could not be downloaded – save their PDFs into D:\Claude_Sales\Expenses (see "Emails Not Scanned" tab).
B60: ACTION | C60: Fill Vendor Code, GL Code and GL Description in 3.Vendor_GL_Codes.xlsx – 116 of 117 lines have no Exps GL Code.
B61: PAY/CHECK | C61: Pay IGST under RCM on Anthropic imports via GSTR-3B (see J7), then claim ITC.
B62: REVIEW | C62: TDS 0.1% (194Q) is applied on Clay Craft and Stitch-9 although their notes say "only if FY purchases > ₹50 L" – confirm FY purchases and set TDS Rate to 0 if below.
B63: REVIEW | C63: Confirm TDS rates with CA (10% rent, 2% contract/brokerage, 10% professional fees).
...

Sheet Invoice Register
A1: Nicobar Design Pvt. Ltd. – Purchase Invoice Register
A2: Add one row per invoice line. Blue cells = inputs; black cells = formulas (Year, Month, Taxable Amount, IGST, CGST, SGST, Invoice Total, TDS Amount, Net Payable). Copy formulas down for new rows.
A4: S.No. | B4: Folder / File | C4: Invoice No. | D4: Invoice Date | E4: Year | F4: Month | G4: Supplier | H4: Supplier GSTIN | I4: Item Code | J4: Description | K4: HSN | L4: Boxes | M4: Quantity | N4: Unit | O4: Rate (₹) | P4: Discount (₹) | Q4: Taxable Amount (₹) | R4: GST Rate | S4: Tax Type | T4: IGST (₹) | U4: CGST (₹) | V4: SGST (₹) | W4: Round Off (₹) | X4: Invoice Total (₹) | Y4: TDS Amount (₹) | Z4: Net Payable (₹) | AA4: Location Code | AB4: Vendor GL Code | AC4: Exps GL Code | AD4: Supplier State | AE4: Buyer GSTIN | AF4: Place of Supply | AG4: Buyer PO No. | AH4: PO Date | AI4: Delivery Note No. | AJ4: Reference No. | AK4: IRN | AL4: Ack No. | AM4: Ack Date | AN4: E-Way Bill No. | AO4: Transporter | AP4: LR No. | AQ4: Vehicle No. | AR4: RCM / GST Compliance | AS4: TDS Section | AT4: TDS Rate
A5: 1 | B5: Clay Craft India Limited\MN-10076-26-27 12.09.26.pdf | C5: MN/10076/26-27 | D5: 46277 | E5: =YEAR(D5) -> 2026 | F5: =TEXT(D5,"mmm") -> Sep | G5: Clay Craft India Limited | H5: 08AAACC6866D1ZO | I5: FG002530 | J5: NB Chip & Dip Platter Madagascar 8 Pcs (NBI015086) | K5: 69120090 | L5: 103 | M5: 824 | N5: SET | O5: 624 | P5: 0 | Q5: =M5*O5-P5 -> 514176 | R5: 0.05 | S5: IGST | T5: =IF(S5="IGST",ROUND(Q5*R5,2),0) -> 25708.8 | U5: =IF(S5="CGST+SGST",ROUND(Q5*R5/2,2),0) -> 0 | V5: =U5 -> 0 | W5: 0.2 | X5: =Q5+T5+U5+V5+W5 -> 539885 | Y5: =ROUND(Q5*AT5,0) -> 514 | Z5: =X5-Y5 -> 539371 | AD5: Rajasthan (08) | AE5: 06AAFCN6567R1ZL | AF5: Haryana (06) | AG5: 26000000212 | AH5: 46150 | AI5: 10077 | AJ5: 10025 | AK5: ae7effee14e9c500367bd89f189cbbe82144949d40cf3289faf00e7361cb9127 | AL5: 172621162836331 | AM5: 2026-09-12 18:39 | AN5: 751669414036 | AO5: Shyam Cargo Movers | AP5: 12047 | AQ5: HR47H6099 | AR5: No RCM – forward charge; goods, IGST 5% charged by supplier. ITC eligible (check GSTR-2B). | AS5: Sec 393(1) – purchase of goods (old 194Q), code 1031. Apply only if FY purchases from this supplier > ₹50 L (on excess). | AT5: 0.001
A6: 2 | B6: Stitch-9\S9-26-27-274 18.09.26.pdf | C6: S9/26-27/274 | D6: 46283 | E6: =YEAR(D6) -> 2026 | F6: =TEXT(D6,"mmm") -> Sep | G6: M/s Stitch-9 | H6: 09AAOFS1968D2ZS | I6: D1451 | J6: Bash Jumpsuit - Silk Blend Loose Fit | K6: 62114290 | M6: 348 | N6: PCS | O6: 2875 | P6: 0 | Q6: =M6*O6-P6 -> 1000500 | R6: 0.18 | S6: IGST | T6: =IF(S6="IGST",ROUND(Q6*R6,2),0) -> 180090 | U6: =IF(S6="CGST+SGST",ROUND(Q6*R6/2,2),0) -> 0 | V6: =U6 -> 0 | W6: 0 | X6: =Q6+T6+U6+V6+W6 -> 1180590 | Y6: =ROUND(Q6*AT6,0) -> 1001 | Z6: =X6-Y6 -> 1179589 | AD6: Uttar Pradesh (09) | AE6: 06AAFCN6567R1ZL | AF6: Haryana (06) | AG6: PO26000001140 | AK6: 99777f8e7b31a4d9e186beec882f4fab746542a5f80f935acb61b37d3d74aa72 | AL6: 142621334812849 | AM6: 18-09-2026 | AN6: 451773976269 | AO6: Kamlesh Tempo Transport | AQ6: DL01LAH1554 | AR6: No RCM – invoice states Reverse Charge: N; goods, IGST 18% charged. ITC eligible (check GSTR-2B). | AS6: Sec 393(1) – purchase of goods (old 194Q), code 1031. Apply only if FY purchases from this supplier > ₹50 L (on excess). | AT6: 0.001
A7: 3 | B7: Quang Vinh Ceramic Co Ltd\06-26QV-NICOBAR 25.09.26.pdf | C7: 06/26QV-NICOBAR | D7: 46290 | E7: =YEAR(D7) -> 2026 | F7: =TEXT(D7,"mmm") -> Sep | G7: Branch of Quang Vinh Ceramic Co., Ltd (Vietnam) | I7: NBI023354 | J7: Ceramic Jug 14.5x8.5x23 cm | K7: 69120010 | M7: 200 | N7: PCE | O7: =10.1*95.8179 -> 967.76079 | P7: 0 | Q7: =M7*O7-P7 -> 193552.16 | R7: 0 | S7: Import (no GST) | T7: =IF(S7="IGST",ROUND(Q7*R7,2),0) -> 0 | U7: =IF(S7="CGST+SGST",ROUND(Q7*R7/2,2),0) -> 0 | V7: =U7 -> 0 | W7: 0 | X7: =Q7+T7+U7+V7+W7 -> 193552.16 | Y7: =ROUND(Q7*AT7,0) -> 0 | Z7: =X7-Y7 -> 193552.16 | AD7: Vietnam (Import) | AE7: 06AAFCN6567R1ZL | AF7: Haryana (06) | AG7: PO26000000358; PO26000000526; PO26000000609 | AJ7: PI NICO25; NICO26; NICO27 | AR7: Not RCM – import of goods: IGST + BCD paid to Customs on Bill of Entry; claim IGST ITC from BoE. | AS7: Not applicable – import of goods from non-resident, no income taxable in India (old 195 / 194Q N/A). | AT7: 0
A8: 4 | B8: Quang Vinh Ceramic Co Ltd\06-26QV-NICOBAR 25.09.26.pdf | C8: 06/26QV-NICOBAR | D8: 46290 | E8: =YEAR(D8) -> 2026 | F8: =TEXT(D8,"mmm") -> Sep | G8: Branch of Quang Vinh Ceramic Co., Ltd (Vietnam) | I8: NBI005679 | J8: Ceramic Plate 21x21.5x1.5 cm | K8: 69120010 | M8: 144 | N8: PCE | O8: =5.4*95.8179 -> 517.41666 | P8: 0 | Q8: =M8*O8-P8 -> 74507.999 | R8: 0 | S8: Import (no GST) | T8: =IF(S8="IGST",ROUND(Q8*R8,2),0) -> 0 | U8: =IF(S8="CGST+SGST",ROUND(Q8*R8/2,2),0) -> 0 | V8: =U8 -> 0 | W8: 0 | X8: =Q8+T8+U8+V8+W8 -> 74507.999 | Y8: =ROUND(Q8*AT8,0) -> 0 | Z8: =X8-Y8 -> 74507.999 | AD8: Vietnam (Import) | AE8: 06AAFCN6567R1ZL | AF8: Haryana (06) | AG8: PO26000000358; PO26000000526; PO26000000609 | AJ8: PI NICO25; NICO26; NICO27 | AR8: Not RCM – import of goods: IGST + BCD paid to Customs on Bill of Entry; claim IGST ITC from BoE. | AS8: Not applicable – import of goods from non-resident, no income taxable in India (old 195 / 194Q N/A). | AT8: 0
A9: 5 | B9: Quang Vinh Ceramic Co Ltd\06-26QV-NICOBAR 25.09.26.pdf | C9: 06/26QV-NICOBAR | D9: 46290 | E9: =YEAR(D9) -> 2026 | F9: =TEXT(D9,"mmm") -> Sep | G9: Branch of Quang Vinh Ceramic Co., Ltd (Vietnam) | I9: NBI005681 | J9: Ceramic Bowl 11x11.5x5 cm | K9: 69120010 | M9: 384 | N9: PCE | O9: =2.3*95.8179 -> 220.38117 | P9: 0 | Q9: =M9*O9-P9 -> 84626.369 | R9: 0 | S9: Import (no GST) | T9: =IF(S9="IGST",ROUND(Q9*R9,2),0) -> 0 | U9: =IF(S9="CGST+SGST",ROUND(Q9*R9/2,2),0) -> 0 | V9: =U9 -> 0 | W9: 0 | X9: =Q9+T9+U9+V9+W9 -> 84626.369 | Y9: =ROUND(Q9*AT9,0) -> 0 | Z9: =X9-Y9 -> 84626.369 | AD9: Vietnam (Import) | AE9: 06AAFCN6567R1ZL | AF9: Haryana (06) | AG9: PO26000000358; PO26000000526; PO26000000609 | AJ9: PI NICO25; NICO26; NICO27 | AR9: Not RCM – import of goods: IGST + BCD paid to Customs on Bill of Entry; claim IGST ITC from BoE. | AS9: Not applicable – import of goods from non-resident, no income taxable in India (old 195 / 194Q N/A). | AT9: 0
A10: 6 | B10: Quang Vinh Ceramic Co Ltd\06-26QV-NICOBAR 25.09.26.pdf | C10: 06/26QV-NICOBAR | D10: 46290 | E10: =YEAR(D10) -> 2026 | F10: =TEXT(D10,"mmm") -> Sep | G10: Branch of Quang Vinh Ceramic Co., Ltd (Vietnam) | I10: NBI005678 | J10: Ceramic Plate 27x26x1.5 cm | K10: 69120010 | M10: 304 | N10: PCE | O10: =6.5*95.8179 -> 622.81635 | P10: 0 | Q10: =M10*O10-P10 -> 189336.17 | R10: 0 | S10: Import (no GST) | T10: =IF(S10="IGST",ROUND(Q10*R10,2),0) -> 0 | U10: =IF(S10="CGST+SGST",ROUND(Q10*R10/2,2),0) -> 0 | V10: =U10 -> 0 | W10: 0 | X10: =Q10+T10+U10+V10+W10 -> 189336.17 | Y10: =ROUND(Q10*AT10,0) -> 0 | Z10: =X10-Y10 -> 189336.17 | AD10: Vietnam (Import) | AE10: 06AAFCN6567R1ZL | AF10: Haryana (06) | AG10: PO26000000358; PO26000000526; PO26000000609 | AJ10: PI NICO25; NICO26; NICO27 | AR10: Not RCM – import of goods: IGST + BCD paid to Customs on Bill of Entry; claim IGST ITC from BoE. | AS10: Not applicable – import of goods from non-resident, no income taxable in India (old 195 / 194Q N/A). | AT10: 0
A11: 7 | B11: Quang Vinh Ceramic Co Ltd\06-26QV-NICOBAR 25.09.26.pdf | C11: 06/26QV-NICOBAR | D11: 46290 | E11: =YEAR(D11) -> 2026 | F11: =TEXT(D11,"mmm") -> Sep | G11: Branch of Quang Vinh Ceramic Co., Ltd (Vietnam) | I11: NBI020668 | J11: Ceramic Bowl 10x9.5x3.5 cm | K11: 69120010 | M11: 432 | N11: PCE | O11: =1.6*95.8179 -> 153.30864 | P11: 0 | Q11: =M11*O11-P11 -> 66229.332 | R11: 0 | S11: Import (no GST) | T11: =IF(S11="IGST",ROUND(Q11*R11,2),0) -> 0 | U11: =IF(S11="CGST+SGST",ROUND(Q11*R11/2,2),0) -> 0 | V11: =U11 -> 0 | W11: 0 | X11: =Q11+T11+U11+V11+W11 -> 66229.332 | Y11: =ROUND(Q11*AT11,0) -> 0 | Z11: =X11-Y11 -> 66229.332 | AD11: Vietnam (Import) | AE11: 06AAFCN6567R1ZL | AF11: Haryana (06) | AG11: PO26000000358; PO26000000526; PO26000000609 | AJ11: PI NICO25; NICO26; NICO27 | AR11: Not RCM – import of goods: IGST + BCD paid to Customs on Bill of Entry; claim IGST ITC from BoE. | AS11: Not applicable – import of goods from non-resident, no income taxable in India (old 195 / 194Q N/A). | AT11: 0
A12: 8 | B12: Quang Vinh Ceramic Co Ltd\06-26QV-NICOBAR 25.09.26.pdf | C12: 06/26QV-NICOBAR | D12: 46290 | E12: =YEAR(D12) -> 2026 | F12: =TEXT(D12,"mmm") -> Sep | G12: Branch of Quang Vinh Ceramic Co., Ltd (Vietnam) | I12: NBI017691 | J12: Ceramic Plate 21x21.5x1.5 cm | K12: 69120010 | M12: 312 | N12: PCE | O12: =5.8*95.8179 -> 555.74382 | P12: 0 | Q12: =M12*O12-P12 -> 173392.07 | R12: 0 | S12: Import (no GST) | T12: =IF(S12="IGST",ROUND(Q12*R12,2),0) -> 0 | U12: =IF(S12="CGST+SGST",ROUND(Q12*R12/2,2),0) -> 0 | V12: =U12 -> 0 | W12: 0 | X12: =Q12+T12+U12+V12+W12 -> 173392.07 | Y12: =ROUND(Q12*AT12,0) -> 0 | Z12: =X12-Y12 -> 173392.07 | AD12: Vietnam (Import) | AE12: 06AAFCN6567R1ZL | AF12: Haryana (06) | AG12: PO26000000358; PO26000000526; PO26000000609 | AJ12: PI NICO25; NICO26; NICO27 | AR12: Not RCM – import of goods: IGST + BCD paid to Customs on Bill of Entry; claim IGST ITC from BoE. | AS12: Not applicable – import of goods from non-resident, no income taxable in India (old 195 / 194Q N/A). | AT12: 0
A13: 9 | B13: Quang Vinh Ceramic Co Ltd\06-26QV-NICOBAR 25.09.26.pdf | C13: 06/26QV-NICOBAR | D13: 46290 | E13: =YEAR(D13) -> 2026 | F13: =TEXT(D13,"mmm") -> Sep | G13: Branch of Quang Vinh Ceramic Co., Ltd (Vietnam) | I13: NBI017690 | J13: Ceramic Plate 21x21.5x1.5 cm | K13: 69120010 | M13: 216 | N13: PCE | O13: =5.8*95.8179 -> 555.74382 | P13: 0 | Q13: =M13*O13-P13 -> 120040.67 | R13: 0 | S13: Import (no GST) | T13: =IF(S13="IGST",ROUND(Q13*R13,2),0) -> 0 | U13: =IF(S13="CGST+SGST",ROUND(Q13*R13/2,2),0) -> 0 | V13: =U13 -> 0 | W13: 0 | X13: =Q13+T13+U13+V13+W13 -> 120040.67 | Y13: =ROUND(Q13*AT13,0) -> 0 | Z13: =X13-Y13 -> 120040.67 | AD13: Vietnam (Import) | AE13: 06AAFCN6567R1ZL | AF13: Haryana (06) | AG13: PO26000000358; PO26000000526; PO26000000609 | AJ13: PI NICO25; NICO26; NICO27 | AR13: Not RCM – import of goods: IGST + BCD paid to Customs on Bill of Entry; claim IGST ITC from BoE. | AS13: Not applicable – import of goods from non-resident, no income taxable in India (old 195 / 194Q N/A). | AT13: 0
A14: 10 | B14: Quang Vinh Ceramic Co Ltd\06-26QV-NICOBAR 25.09.26.pdf | C14: 06/26QV-NICOBAR | D14: 46290 | E14: =YEAR(D14) -> 2026 | F14: =TEXT(D14,"mmm") -> Sep | G14: Branch of Quang Vinh Ceramic Co., Ltd (Vietnam) | I14: NBI017689 | J14: Ceramic Plate 27x26x1.5 cm | K14: 69120010 | M14: 200 | N14: PCE | O14: =6.9*95.8179 -> 661.14351 | P14: 0 | Q14: =M14*O14-P14 -> 132228.7 | R14: 0 | S14: Import (no GST) | T14: =IF(S14="IGST",ROUND(Q14*R14,2),0) -> 0 | U14: =IF(S14="CGST+SGST",ROUND(Q14*R14/2,2),0) -> 0 | V14: =U14 -> 0 | W14: 0 | X14: =Q14+T14+U14+V14+W14 -> 132228.7 | Y14: =ROUND(Q14*AT14,0) -> 0 | Z14: =X14-Y14 -> 132228.7 | AD14: Vietnam (Import) | AE14: 06AAFCN6567R1ZL | AF14: Haryana (06) | AG14: PO26000000358; PO26000000526; PO26000000609 | AJ14: PI NICO25; NICO26; NICO27 | AR14: Not RCM – import of goods: IGST + BCD paid to Customs on Bill of Entry; claim IGST ITC from BoE. | AS14: Not applicable – import of goods from non-resident, no income taxable in India (old 195 / 194Q N/A). | AT14: 0
A15: 11 | B15: Quang Vinh Ceramic Co Ltd\06-26QV-NICOBAR 25.09.26.pdf | C15: 06/26QV-NICOBAR | D15: 46290 | E15: =YEAR(D15) -> 2026 | F15: =TEXT(D15,"mmm") -> Sep | G15: Branch of Quang Vinh Ceramic Co., Ltd (Vietnam) | I15: NBI023349 | J15: Ceramic Cup 13x10.2x10 cm | K15: 69120010 | M15: 256 | N15: PCE | O15: =3.95*95.8179 -> 378.48071 | P15: 0 | Q15: =M15*O15-P15 -> 96891.06 | R15: 0 | S15: Import (no GST) | T15: =IF(S15="IGST",ROUND(Q15*R15,2),0) -> 0 | U15: =IF(S15="CGST+SGST",ROUND(Q15*R15/2,2),0) -> 0 | V15: =U15 -> 0 | W15: 0 | X15: =Q15+T15+U15+V15+W15 -> 96891.06 | Y15: =ROUND(Q15*AT15,0) -> 0 | Z15: =X15-Y15 -> 96891.06 | AD15: Vietnam (Import) | AE15: 06AAFCN6567R1ZL | AF15: Haryana (06) | AG15: PO26000000358; PO26000000526; PO26000000609 | AJ15: PI NICO25; NICO26; NICO27 | AR15: Not RCM – import of goods: IGST + BCD paid to Customs on Bill of Entry; claim IGST ITC from BoE. | AS15: Not applicable – import of goods from non-resident, no income taxable in India (old 195 / 194Q N/A). | AT15: 0
A16: 12 | B16: Quang Vinh Ceramic Co Ltd\06-26QV-NICOBAR 25.09.26.pdf | C16: 06/26QV-NICOBAR | D16: 46290 | E16: =YEAR(D16) -> 2026 | F16: =TEXT(D16,"mmm") -> Sep | G16: Branch of Quang Vinh Ceramic Co., Ltd (Vietnam) | J16: Repacking Charge | M16: 1 | N16: LOT | O16: =350*95.8179 -> 33536.265 | P16: 0 | Q16: =M16*O16-P16 -> 33536.265 | R16: 0 | S16: Import (no GST) | T16: =IF(S16="IGST",ROUND(Q16*R16,2),0) -> 0 | U16: =IF(S16="CGST+SGST",ROUND(Q16*R16/2,2),0) -> 0 | V16: =U16 -> 0 | W16: 0 | X16: =Q16+T16+U16+V16+W16 -> 33536.265 | Y16: =ROUND(Q16*AT16,0) -> 0 | Z16: =X16-Y16 -> 33536.265 | AD16: Vietnam (Import) | AE16: 06AAFCN6567R1ZL | AF16: Haryana (06) | AG16: PO26000000358; PO26000000526; PO26000000609 | AJ16: PI NICO25; NICO26; NICO27 | AR16: Not RCM – import of goods: IGST + BCD paid to Customs on Bill of Entry; claim IGST ITC from BoE. | AS16: Not applicable – import of goods from non-resident, no income taxable in India (old 195 / 194Q N/A). | AT16: 0
A17: 13 | B17: Shreyas Gaikwad\S-09-01 15.09.26.pdf | C17: S#09/01 | D17: 46280 | E17: =YEAR(D17) -> 2026 | F17: =TEXT(D17,"mmm") -> Sep | G17: Shreyas Gaikwad | J17: Influencer Collaboration | M17: 1 | O17: 30000 | P17: 0 | Q17: =M17*O17-P17 -> 30000 | R17: 0 | S17: No GST (unregistered) | T17: =IF(S17="IGST",ROUND(Q17*R17,2),0) -> 0 | U17: =IF(S17="CGST+SGST",ROUND(Q17*R17/2,2),0) -> 0 | V17: =U17 -> 0 | W17: 0 | X17: =Q17+T17+U17+V17+W17 -> 30000 | Y17: =ROUND(Q17*AT17,0) -> 0 | Z17: =X17-Y17 -> 30000 | AE17: 07AAFCN6567R1ZJ | AF17: Delhi (07) | AR17: No RCM – unregistered individual; influencer/advertising service not notified under Sec 9(3)/9(4). No GST, no ITC. | AS17: Sec 393(1) – professional/advertising fees (old 194J), 10%, code 1027. Nil now: ₹30,000 is below ₹50,000 FY threshold; deduct 10% if FY total exceeds it. | AT17: 0
A18: 14 | B18: DPS Telecom (OPC) Private Limited\09-UPTIN26003027 23.09.26.pdf | C18: 09-UPTIN26003027 | D18: 46288 | E18: =YEAR(D18) -> 2026 | F18: =TEXT(D18,"mmm") -> Sep | G18: DPS Telecom (OPC) Private Limited | H18: 09AAFCD2760A1Z1 | J18: Internet Access Services – plan DPS-200MB-UL-3MN, 26/09/2026–25/12/2026 (Shop 272A, DLF Mall of India, Noida) | K18: 998422 | M18: 1 | N18: LOT | O18: 2847.46 | P18: 0 | Q18: =M18*O18-P18 -> 2847.46 | R18: 0.18 | S18: CGST+SGST | T18: =IF(S18="IGST",ROUND(Q18*R18,2),0) -> 0 | U18: =IF(S18="CGST+SGST",ROUND(Q18*R18/2,2),0) -> 256.27 | V18: =U18 -> 256.27 | W18: 0 | X18: =Q18+T18+U18+V18+W18 -> 3360 | Y18: =ROUND(Q18*AT18,0) -> 0 | Z18: =X18-Y18 -> 3360 | AD18: Uttar Pradesh (09) | AE18: 09AAFCN6567R1ZF | AF18: Uttar Pradesh (09) | AJ18: Customer ID DPS001879 | AR18: No RCM – forward charge; CGST 9% + SGST 9% charged by supplier (T&C "subject to reverse charge" line is boilerplate). ITC eligible against UP GSTIN (check GSTR-2B). | AS18: Sec 393(1) – contract/service (old 194C). Nil – ₹2,847 below single-payment threshold; review if FY total > ₹1 L. | AT18: 0
A19: 15 | B19: Vraj Commercial Private Limited\CH-0562-26-27 01.09.26.pdf | C19: CH/0562/26-27 | D19: 46266 | E19: =YEAR(D19) -> 2026 | F19: =TEXT(D19,"mmm") -> Sep | G19: Vraj Commercial Private Limited | H19: 22AAHCV7110N1Z8 | J19: CAM Charges for Sep-26 (Nicobar UG 26, Zora The Mall, Raipur) | K19: 998533 | M19: 2354 | N19: SQF | O19: 25 | P19: 0 | Q19: =M19*O19-P19 -> 58850 | R19: 0.18 | S19: CGST+SGST | T19: =IF(S19="IGST",ROUND(Q19*R19,2),0) -> 0 | U19: =IF(S19="CGST+SGST",ROUND(Q19*R19/2,2),0) -> 5296.5 | V19: =U19 -> 5296.5 | W19: 0 | X19: =Q19+T19+U19+V19+W19 -> 69443 | Y19: =ROUND(Q19*AT19,0) -> 1177 | Z19: =X19-Y19 -> 68266 | AD19: Chhattisgarh (22) | AE19: 22AAFCN6567R1ZR | AF19: Chhattisgarh (22) | AK19: 925b19d93bc7d631c6e68641135eb3ac2e3237db55bd5373b5baa3e915eed850 | AL19: 182623628025173 | AM19: 01-09-2026 | AR19: No RCM – forward charge; CGST 9% + SGST 9% charged. ITC eligible against CG GSTIN (check GSTR-2B). | AS19: Sec 393(1) – contract/service (old 194C), 2% (company). Confirm with CA. | AT19: 0.02
A20: 16 | B20: Vraj Commercial Private Limited\CH-0562-26-27 01.09.26.pdf | C20: CH/0562/26-27 | D20: 46266 | E20: =YEAR(D20) -> 2026 | F20: =TEXT(D20,"mmm") -> Sep | G20: Vraj Commercial Private Limited | H20: 22AAHCV7110N1Z8 | J20: HVAC Charges for Sep-26 (Nicobar UG 26, Zora The Mall, Raipur) | K20: 997319 | M20: 2354 | N20: SQF | O20: 10 | P20: 0 | Q20: =M20*O20-P20 -> 23540 | R20: 0.18 | S20: CGST+SGST | T20: =IF(S20="IGST",ROUND(Q20*R20,2),0) -> 0 | U20: =IF(S20="CGST+SGST",ROUND(Q20*R20/2,2),0) -> 2118.6 | V20: =U20 -> 2118.6 | W20: 0 | X20: =Q20+T20+U20+V20+W20 -> 27777.2 | Y20: =ROUND(Q20*AT20,0) -> 471 | Z20: =X20-Y20 -> 27306.2 | AD20: Chhattisgarh (22) | AE20: 22AAFCN6567R1ZR | AF20: Chhattisgarh (22) | AK20: 925b19d93bc7d631c6e68641135eb3ac2e3237db55bd5373b5baa3e915eed850 | AL20: 182623628025173 | AM20: 01-09-2026 | AR20: No RCM – forward charge; CGST 9% + SGST 9% charged. ITC eligible against CG GSTIN (check GSTR-2B). | AS20: Sec 393(1) – contract/service (old 194C), 2% (company). Confirm with CA. | AT20: 0.02
A21: 17 | B21: Vraj Commercial Private Limited\EL-DG-0545-26-27 02.09.26.pdf | C21: EL-DG/0545/26-27 | D21: 46267 | E21: =YEAR(D21) -> 2026 | F21: =TEXT(D21,"mmm") -> Sep | G21: Vraj Commercial Private Limited | H21: 22AAHCV7110N1Z8 | J21: Support Service to Electricity – Electricity Consumption Aug-26 – 1,428.30 UNT @ ₹13.50 (Opening 19197.4, Closing 20625.7) | K21: 998631 | M21: 1 | N21: LOT | O21: 19282 | P21: 0 | Q21: =M21*O21-P21 -> 19282 | R21: 0.18 | S21: CGST+SGST | T21: =IF(S21="IGST",ROUND(Q21*R21,2),0) -> 0 | U21: =IF(S21="CGST+SGST",ROUND(Q21*R21/2,2),0) -> 1735.38 | V21: =U21 -> 1735.38 | W21: 0 | X21: =Q21+T21+U21+V21+W21 -> 22752.76 | Y21: =ROUND(Q21*AT21,0) -> 386 | Z21: =X21-Y21 -> 22366.76 | AD21: Chhattisgarh (22) | AE21: 22AAFCN6567R1ZR | AF21: Chhattisgarh (22) | AK21: b323e2f2471536236b6c3b9b523a05bc7d63c88ce2ddc6756db926d4b6846fdc | AL21: 182623687389810 | AM21: 07-09-2026 | AR21: No RCM – forward charge; CGST 9% + SGST 9% charged on electricity support service. ITC eligible (check GSTR-2B). | AS21: Sec 393(1) – contract/service (old 194C), 2% (company). Confirm with CA whether electricity pass-through is excluded. | AT21: 0.02
A22: 18 | B22: Vraj Commercial Private Limited\EL-DG-0545-26-27 02.09.26.pdf | C22: EL-DG/0545/26-27 | D22: 46267 | E22: =YEAR(D22) -> 2026 | F22: =TEXT(D22,"mmm") -> Sep | G22: Vraj Commercial Private Limited | H22: 22AAHCV7110N1Z8 | J22: Support Service to Electricity – Electricity – MD Charges 18.01 KVA @ ₹400.00 | K22: 998631 | M22: 1 | N22: LOT | O22: 7204 | P22: 0 | Q22: =M22*O22-P22 -> 7204 | R22: 0.18 | S22: CGST+SGST | T22: =IF(S22="IGST",ROUND(Q22*R22,2),0) -> 0 | U22: =IF(S22="CGST+SGST",ROUND(Q22*R22/2,2),0) -> 648.36 | V22: =U22 -> 648.36 | W22: 0 | X22: =Q22+T22+U22+V22+W22 -> 8500.72 | Y22: =ROUND(Q22*AT22,0) -> 144 | Z22: =X22-Y22 -> 8356.72 | AD22: Chhattisgarh (22) | AE22: 22AAFCN6567R1ZR | AF22: Chhattisgarh (22) | AK22: b323e2f2471536236b6c3b9b523a05bc7d63c88ce2ddc6756db926d4b6846fdc | AL22: 182623687389810 | AM22: 07-09-2026 | AR22: No RCM – forward charge; CGST 9% + SGST 9% charged on electricity support service. ITC eligible (check GSTR-2B). | AS22: Sec 393(1) – contract/service (old 194C), 2% (company). Confirm with CA whether electricity pass-through is excluded. | AT22: 0.02
A23: 19 | B23: Vraj Commercial Private Limited\EL-DG-0545-26-27 02.09.26.pdf | C23: EL-DG/0545/26-27 | D23: 46267 | E23: =YEAR(D23) -> 2026 | F23: =TEXT(D23,"mmm") -> Sep | G23: Vraj Commercial Private Limited | H23: 22AAHCV7110N1Z8 | J23: Support Service to Electricity – DG Consumption Aug-26 – 9.24 UNT @ ₹33.77 | K23: 998631 | M23: 1 | N23: LOT | O23: 312 | P23: 0 | Q23: =M23*O23-P23 -> 312 | R23: 0.18 | S23: CGST+SGST | T23: =IF(S23="IGST",ROUND(Q23*R23,2),0) -> 0 | U23: =IF(S23="CGST+SGST",ROUND(Q23*R23/2,2),0) -> 28.08 | V23: =U23 -> 28.08 | W23: 0 | X23: =Q23+T23+U23+V23+W23 -> 368.16 | Y23: =ROUND(Q23*AT23,0) -> 6 | Z23: =X23-Y23 -> 362.16 | AD23: Chhattisgarh (22) | AE23: 22AAFCN6567R1ZR | AF23: Chhattisgarh (22) | AK23: b323e2f2471536236b6c3b9b523a05bc7d63c88ce2ddc6756db926d4b6846fdc | AL23: 182623687389810 | AM23: 07-09-2026 | AR23: No RCM – forward charge; CGST 9% + SGST 9% charged on electricity support service. ITC eligible (check GSTR-2B). | AS23: Sec 393(1) – contract/service (old 194C), 2% (company). Confirm with CA whether electricity pass-through is excluded. | AT23: 0.02
A24: 20 | B24: Vraj Commercial Private Limited\EL-DG-0545-26-27 02.09.26.pdf | C24: EL-DG/0545/26-27 | D24: 46267 | E24: =YEAR(D24) -> 2026 | F24: =TEXT(D24,"mmm") -> Sep | G24: Vraj Commercial Private Limited | H24: 22AAHCV7110N1Z8 | J24: Support Service to Electricity – Electricity Consumption Jul-26 Rate Diff – 1,479.20 UNT @ ₹1.28 | K24: 998631 | M24: 1 | N24: LOT | O24: 1893 | P24: 0 | Q24: =M24*O24-P24 -> 1893 | R24: 0.18 | S24: CGST+SGST | T24: =IF(S24="IGST",ROUND(Q24*R24,2),0) -> 0 | U24: =IF(S24="CGST+SGST",ROUND(Q24*R24/2,2),0) -> 170.37 | V24: =U24 -> 170.37 | W24: 0 | X24: =Q24+T24+U24+V24+W24 -> 2233.74 | Y24: =ROUND(Q24*AT24,0) -> 38 | Z24: =X24-Y24 -> 2195.74 | AD24: Chhattisgarh (22) | AE24: 22AAFCN6567R1ZR | AF24: Chhattisgarh (22) | AK24: b323e2f2471536236b6c3b9b523a05bc7d63c88ce2ddc6756db926d4b6846fdc | AL24: 182623687389810 | AM24: 07-09-2026 | AR24: No RCM – forward charge; CGST 9% + SGST 9% charged on electricity support service. ITC eligible (check GSTR-2B). | AS24: Sec 393(1) – contract/service (old 194C), 2% (company). Confirm with CA whether electricity pass-through is excluded. | AT24: 0.02
A25: 21 | B25: Vraj Commercial Private Limited\EL-DG-0545-26-27 02.09.26.pdf | C25: EL-DG/0545/26-27 | D25: 46267 | E25: =YEAR(D25) -> 2026 | F25: =TEXT(D25,"mmm") -> Sep | G25: Vraj Commercial Private Limited | H25: 22AAHCV7110N1Z8 | J25: Support Service to Electricity – Electricity – MD Charges Jul-26 Rate Diff – 18.01 KVA @ ₹24.99 | K25: 998631 | M25: 1 | N25: LOT | O25: 450 | P25: 0 | Q25: =M25*O25-P25 -> 450 | R25: 0.18 | S25: CGST+SGST | T25: =IF(S25="IGST",ROUND(Q25*R25,2),0) -> 0 | U25: =IF(S25="CGST+SGST",ROUND(Q25*R25/2,2),0) -> 40.5 | V25: =U25 -> 40.5 | W25: 0 | X25: =Q25+T25+U25+V25+W25 -> 531 | Y25: =ROUND(Q25*AT25,0) -> 9 | Z25: =X25-Y25 -> 522 | AD25: Chhattisgarh (22) | AE25: 22AAFCN6567R1ZR | AF25: Chhattisgarh (22) | AK25: b323e2f2471536236b6c3b9b523a05bc7d63c88ce2ddc6756db926d4b6846fdc | AL25: 182623687389810 | AM25: 07-09-2026 | AR25: No RCM – forward charge; CGST 9% + SGST 9% charged on electricity support service. ITC eligible (check GSTR-2B). | AS25: Sec 393(1) – contract/service (old 194C), 2% (company). Confirm with CA whether electricity pass-through is excluded. | AT25: 0.02
A26: 22 | B26: Vraj Commercial Private Limited\Rent-0613-26-27 12.09.26.pdf | C26: Rent/0613/26-27 | D26: 46277 | E26: =YEAR(D26) -> 2026 | F26: =TEXT(D26,"mmm") -> Sep | G26: Vraj Commercial Private Limited | H26: 22AAHCV7110N1Z8 | J26: Rental Services – 12% Pure Revenue Share on ₹8,40,218 for Aug-2026 (Zora The Mall, Raipur) | K26: 997212 | M26: 1 | N26: LOT | O26: 100826 | P26: 0 | Q26: =M26*O26-P26 -> 100826 | R26: 0.18 | S26: CGST+SGST | T26: =IF(S26="IGST",ROUND(Q26*R26,2),0) -> 0 | U26: =IF(S26="CGST+SGST",ROUND(Q26*R26/2,2),0) -> 9074.34 | V26: =U26 -> 9074.34 | W26: 0 | X26: =Q26+T26+U26+V26+W26 -> 118974.68 | Y26: =ROUND(Q26*AT26,0) -> 10083 | Z26: =X26-Y26 -> 108891.68 | AD26: Chhattisgarh (22) | AE26: 22AAFCN6567R1ZR | AF26: Chhattisgarh (22) | AK26: 8f5c80cdb0718df6b4c2b079ecef652f6659df643aafccf0686f7afb3a4dd8d7 | AL26: 182623774792279 | AM26: 15-09-2026 | AR26: No RCM – forward charge; CGST 9% + SGST 9% on rent. ITC eligible (check GSTR-2B). | AS26: Sec 393(1) – rent of land/building (old 194-I), 10%. | AT26: 0.1
A27: 23 | B27: Anthropic PBC\E87270F6-0001 22.04.26.pdf | C27: E87270F6-0001 | D27: 46134 | E27: =YEAR(D27) -> 2026 | F27: =TEXT(D27,"mmm") -> Apr | G27: Anthropic, PBC (USA) | J27: Claude API – one-time credit purchase (USD 10.00 @ ₹93.8351/USD) | M27: 1 | N27: NOS | O27: =10*93.8351 -> 938.351 | P27: 0 | Q27: =M27*O27-P27 -> 938.351 | R27: 0 | S27: Import (no GST) | T27: =IF(S27="IGST",ROUND(Q27*R27,2),0) -> 0 | U27: =IF(S27="CGST+SGST",ROUND(Q27*R27/2,2),0) -> 0 | V27: =U27 -> 0 | W27: 0 | X27: =Q27+T27+U27+V27+W27 -> 938.351 | Y27: =ROUND(Q27*AT27,0) -> 0 | Z27: =X27-Y27 -> 938.351 | AD27: USA (Import) | AE27: 07AAFCN6567R1ZJ | AF27: Delhi (07) | AJ27: Supplier India GST (OIDAR) 9924USA29003OSI | AR27: RCM – import of service; invoice says tax payable on reverse charge. Nicobar to pay IGST 18% on ₹ value via GSTR-3B and claim ITC. | AS27: Non-resident (old Sec 195) – no TDS if no PE in India / DTAA; confirm with CA (Form 15CA/CB for remittance). | AT27: 0
A28: 24 | B28: Anthropic PBC\E87270F6-0002 22.04.26.pdf | C28: E87270F6-0002 | D28: 46134 | E28: =YEAR(D28) -> 2026 | F28: =TEXT(D28,"mmm") -> Apr | G28: Anthropic, PBC (USA) | J28: Claude API – one-time credit purchase (USD 90.00 @ ₹93.8351/USD) | M28: 1 | N28: NOS | O28: =90*93.8351 -> 8445.159 | P28: 0 | Q28: =M28*O28-P28 -> 8445.159 | R28: 0 | S28: Import (no GST) | T28: =IF(S28="IGST",ROUND(Q28*R28,2),0) -> 0 | U28: =IF(S28="CGST+SGST",ROUND(Q28*R28/2,2),0) -> 0 | V28: =U28 -> 0 | W28: 0 | X28: =Q28+T28+U28+V28+W28 -> 8445.159 | Y28: =ROUND(Q28*AT28,0) -> 0 | Z28: =X28-Y28 -> 8445.159 | AD28: USA (Import) | AE28: 07AAFCN6567R1ZJ | AF28: Delhi (07) | AJ28: Supplier India GST (OIDAR) 9924USA29003OSI | AR28: RCM – import of service; invoice says tax payable on reverse charge. Nicobar to pay IGST 18% on ₹ value via GSTR-3B and claim ITC. | AS28: Non-resident (old Sec 195) – no TDS if no PE in India / DTAA; confirm with CA (Form 15CA/CB for remittance). | AT28: 0
A29: 25 | B29: Anthropic PBC\E87270F6-0003 20.05.26.pdf | C29: E87270F6-0003 | D29: 46162 | E29: =YEAR(D29) -> 2026 | F29: =TEXT(D29,"mmm") -> May | G29: Anthropic, PBC (USA) | J29: Claude API – one-time credit purchase (USD 200.00 @ ₹96.8441/USD) | M29: 1 | N29: NOS | O29: =200*96.8441 -> 19368.82 | P29: 0 | Q29: =M29*O29-P29 -> 19368.82 | R29: 0 | S29: Import (no GST) | T29: =IF(S29="IGST",ROUND(Q29*R29,2),0) -> 0 | U29: =IF(S29="CGST+SGST",ROUND(Q29*R29/2,2),0) -> 0 | V29: =U29 -> 0 | W29: 0 | X29: =Q29+T29+U29+V29+W29 -> 19368.82 | Y29: =ROUND(Q29*AT29,0) -> 0 | Z29: =X29-Y29 -> 19368.82 | AD29: USA (Import) | AE29: 07AAFCN6567R1ZJ | AF29: Delhi (07) | AJ29: Supplier India GST (OIDAR) 9924USA29003OSI | AR29: RCM – import of service; invoice says tax payable on reverse charge. Nicobar to pay IGST 18% on ₹ value via GSTR-3B and claim ITC. | AS29: Non-resident (old Sec 195) – no TDS if no PE in India / DTAA; confirm with CA (Form 15CA/CB for remittance). | AT29: 0
A30: 26 | B30: Anthropic PBC\E87270F6-0004 23.07.26.pdf | C30: E87270F6-0004 | D30: 46226 | E30: =YEAR(D30) -> 2026 | F30: =TEXT(D30,"mmm") -> Jul | G30: Anthropic, PBC (USA) | J30: Claude API – one-time credit purchase (USD 100.00 @ ₹96.5431/USD) | M30: 1 | N30: NOS | O30: =100*96.5431 -> 9654.31 | P30: 0 | Q30: =M30*O30-P30 -> 9654.31 | R30: 0 | S30: Import (no GST) | T30: =IF(S30="IGST",ROUND(Q30*R30,2),0) -> 0 | U30: =IF(S30="CGST+SGST",ROUND(Q30*R30/2,2),0) -> 0 | V30: =U30 -> 0 | W30: 0 | X30: =Q30+T30+U30+V30+W30 -> 9654.31 | Y30: =ROUND(Q30*AT30,0) -> 0 | Z30: =X30-Y30 -> 9654.31 | AD30: USA (Import) | AE30: 07AAFCN6567R1ZJ | AF30: Delhi (07) | AJ30: Supplier India GST (OIDAR) 9924USA29003OSI | AR30: RCM – import of service; invoice says tax payable on reverse charge. Nicobar to pay IGST 18% on ₹ value via GSTR-3B and claim ITC. | AS30: Non-resident (old Sec 195) – no TDS if no PE in India / DTAA; confirm with CA (Form 15CA/CB for remittance). | AT30: 0
A31: 27 | B31: Anthropic PBC\E87270F6-0005 30.07.26.pdf | C31: E87270F6-0005 | D31: 46233 | E31: =YEAR(D31) -> 2026 | F31: =TEXT(D31,"mmm") -> Jul | G31: Anthropic, PBC (USA) | J31: Claude API – one-time credit purchase (USD 100.00 @ ₹95.7327/USD) | K31: 998315 | M31: 1 | N31: NOS | O31: =100*95.7327 -> 9573.27 | P31: 0 | Q31: =M31*O31-P31 -> 9573.27 | R31: 0 | S31: Import (no GST) | T31: =IF(S31="IGST",ROUND(Q31*R31,2),0) -> 0 | U31: =IF(S31="CGST+SGST",ROUND(Q31*R31/2,2),0) -> 0 | V31: =U31 -> 0 | W31: 0 | X31: =Q31+T31+U31+V31+W31 -> 9573.27 | Y31: =ROUND(Q31*AT31,0) -> 0 | Z31: =X31-Y31 -> 9573.27 | AD31: USA (Import) | AE31: 07AAFCN6567R1ZJ | AF31: Delhi (07) | AJ31: Supplier India GST (OIDAR) 9924USA29003OSI | AR31: RCM – import of service; invoice says tax payable on reverse charge. Nicobar to pay IGST 18% on ₹ value via GSTR-3B and claim ITC. | AS31: Non-resident (old Sec 195) – no TDS if no PE in India / DTAA; confirm with CA (Form 15CA/CB for remittance). | AT31: 0
A32: 28 | B32: Anthropic PBC\E87270F6-0006 17.08.26.pdf | C32: E87270F6-0006 | D32: 46251 | E32: =YEAR(D32) -> 2026 | F32: =TEXT(D32,"mmm") -> Aug | G32: Anthropic, PBC (USA) | J32: Claude API – one-time credit purchase (USD 100.00 @ ₹95.6019/USD) | K32: 998315 | M32: 1 | N32: NOS | O32: =100*95.6019 -> 9560.19 | P32: 0 | Q32: =M32*O32-P32 -> 9560.19 | R32: 0 | S32: Import (no GST) | T32: =IF(S32="IGST",ROUND(Q32*R32,2),0) -> 0 | U32: =IF(S32="CGST+SGST",ROUND(Q32*R32/2,2),0) -> 0 | V32: =U32 -> 0 | W32: 0 | X32: =Q32+T32+U32+V32+W32 -> 9560.19 | Y32: =ROUND(Q32*AT32,0) -> 0 | Z32: =X32-Y32 -> 9560.19 | AD32: USA (Import) | AE32: 07AAFCN6567R1ZJ | AF32: Delhi (07) | AJ32: Supplier India GST (OIDAR) 9924USA29003OSI | AR32: RCM – import of service; invoice says tax payable on reverse charge. Nicobar to pay IGST 18% on ₹ value via GSTR-3B and claim ITC. | AS32: Non-resident (old Sec 195) – no TDS if no PE in India / DTAA; confirm with CA (Form 15CA/CB for remittance). | AT32: 0
A33: 29 | B33: Anthropic PBC\E87270F6-0007 02.09.26.pdf | C33: E87270F6-0007 | D33: 46267 | E33: =YEAR(D33) -> 2026 | F33: =TEXT(D33,"mmm") -> Sep | G33: Anthropic, PBC (USA) | J33: Claude API – one-time credit purchase (USD 20.00 @ ₹94.9701/USD) | K33: 998315 | M33: 1 | N33: NOS | O33: =20*94.9701 -> 1899.402 | P33: 0 | Q33: =M33*O33-P33 -> 1899.402 | R33: 0 | S33: Import (no GST) | T33: =IF(S33="IGST",ROUND(Q33*R33,2),0) -> 0 | U33: =IF(S33="CGST+SGST",ROUND(Q33*R33/2,2),0) -> 0 | V33: =U33 -> 0 | W33: 0 | X33: =Q33+T33+U33+V33+W33 -> 1899.402 | Y33: =ROUND(Q33*AT33,0) -> 0 | Z33: =X33-Y33 -> 1899.402 | AD33: USA (Import) | AE33: 07AAFCN6567R1ZJ | AF33: Delhi (07) | AJ33: Supplier India GST (OIDAR) 9924USA29003OSI | AR33: RCM – import of service; invoice says tax payable on reverse charge. Nicobar to pay IGST 18% on ₹ value via GSTR-3B and claim ITC. | AS33: Non-resident (old Sec 195) – no TDS if no PE in India / DTAA; confirm with CA (Form 15CA/CB for remittance). | AT33: 0
A34: 30 | B34: Anthropic PBC\E87270F6-0008 03.09.26.pdf | C34: E87270F6-0008 | D34: 46268 | E34: =YEAR(D34) -> 2026 | F34: =TEXT(D34,"mmm") -> Sep | G34: Anthropic, PBC (USA) | J34: Claude API – one-time credit purchase (USD 100.00 @ ₹94.4688/USD) | K34: 998315 | M34: 1 | N34: NOS | O34: =100*94.4688 -> 9446.88 | P34: 0 | Q34: =M34*O34-P34 -> 9446.88 | R34: 0 | S34: Import (no GST) | T34: =IF(S34="IGST",ROUND(Q34*R34,2),0) -> 0 | U34: =IF(S34="CGST+SGST",ROUND(Q34*R34/2,2),0) -> 0 | V34: =U34 -> 0 | W34: 0 | X34: =Q34+T34+U34+V34+W34 -> 9446.88 | Y34: =ROUND(Q34*AT34,0) -> 0 | Z34: =X34-Y34 -> 9446.88 | AD34: USA (Import) | AE34: 07AAFCN6567R1ZJ | AF34: Delhi (07) | AJ34: Supplier India GST (OIDAR) 9924USA29003OSI | AR34: RCM – import of service; invoice says tax payable on reverse charge. Nicobar to pay IGST 18% on ₹ value via GSTR-3B and claim ITC. | AS34: Non-resident (old Sec 195) – no TDS if no PE in India / DTAA; confirm with CA (Form 15CA/CB for remittance). | AT34: 0
A35: 31 | B35: Anthropic PBC\E87270F6-0009 07.09.26.pdf | C35: E87270F6-0009 | D35: 46272 | E35: =YEAR(D35) -> 2026 | F35: =TEXT(D35,"mmm") -> Sep | G35: Anthropic, PBC (USA) | J35: Claude API – one-time credit purchase (USD 100.00 @ ₹94.4467/USD) | K35: 998315 | M35: 1 | N35: NOS | O35: =100*94.4467 -> 9444.67 | P35: 0 | Q35: =M35*O35-P35 -> 9444.67 | R35: 0 | S35: Import (no GST) | T35: =IF(S35="IGST",ROUND(Q35*R35,2),0) -> 0 | U35: =IF(S35="CGST+SGST",ROUND(Q35*R35/2,2),0) -> 0 | V35: =U35 -> 0 | W35: 0 | X35: =Q35+T35+U35+V35+W35 -> 9444.67 | Y35: =ROUND(Q35*AT35,0) -> 0 | Z35: =X35-Y35 -> 9444.67 | AD35: USA (Import) | AE35: 07AAFCN6567R1ZJ | AF35: Delhi (07) | AJ35: Supplier India GST (OIDAR) 9924USA29003OSI | AR35: RCM – import of service; invoice says tax payable on reverse charge. Nicobar to pay IGST 18% on ₹ value via GSTR-3B and claim ITC. | AS35: Non-resident (old Sec 195) – no TDS if no PE in India / DTAA; confirm with CA (Form 15CA/CB for remittance). | AT35: 0
A36: 32 | B36: Antya Web Private Limited\TCAI-513-2627 12.09.26.pdf | C36: TCAI-513-2627 | D36: 46277 | E36: =YEAR(D36) -> 2026 | F36: =TEXT(D36,"mmm") -> Sep | G36: Antya Web Private Limited | H36: 33AAGCA7143R1ZA | J36: AI-Native Consulting to Nicobar – 1 month (12 Sep – 11 Oct 2026) | K36: 999293 | M36: 1 | N36: LOT | O36: 1200000 | P36: 0 | Q36: =M36*O36-P36 -> 1200000 | R36: 0.18 | S36: IGST | T36: =IF(S36="IGST",ROUND(Q36*R36,2),0) -> 216000 | U36: =IF(S36="CGST+SGST",ROUND(Q36*R36/2,2),0) -> 0 | V36: =U36 -> 0 | W36: 0 | X36: =Q36+T36+U36+V36+W36 -> 1416000 | Y36: =ROUND(Q36*AT36,0) -> 120000 | Z36: =X36-Y36 -> 1296000 | AD36: Tamil Nadu (33) | AE36: 07AAFCN6567R1ZJ | AF36: Delhi (07) | AR36: No RCM – forward charge; IGST 18% charged by supplier. ITC eligible (check GSTR-2B). MSME (UDYAM-TN-02-0471769) – pay within 45 days. Due date 16-09-2026. | AS36: Sec 393(1) – fees for professional/technical services (old 194J), 10%. Confirm with CA. | AT36: 0.1
A37: 33 | B37: Pine Labs Limited\INV092609248716 10.09.26.pdf | C37: INV092609248716 | D37: 46275 | E37: =YEAR(D37) -> 2026 | F37: =TEXT(D37,"mmm") -> Sep | G37: Pine Labs Limited | H37: 09AACCP7457K1ZV | J37: Plutus PoS Service Fee – Aug-26 (line 1) | K37: 998319 | M37: 1 | N37: NOS | O37: 1200 | P37: 0 | Q37: =M37*O37-P37 -> 1200 | R37: 0.18 | S37: IGST | T37: =IF(S37="IGST",ROUND(Q37*R37,2),0) -> 216 | U37: =IF(S37="CGST+SGST",ROUND(Q37*R37/2,2),0) -> 0 | V37: =U37 -> 0 | W37: 0 | X37: =Q37+T37+U37+V37+W37 -> 1416 | Y37: =ROUND(Q37*AT37,0) -> 24 | Z37: =X37-Y37 -> 1392 | AD37: Uttar Pradesh (09) | AE37: 07AAFCN6567R1ZJ | AF37: Delhi (07) | AG37: 12477167 | AH37: 45217 | AK37: 839bd782fcfc91fa31e6f83f9b07b14947d83dfd1799675967bc0255960a2c1d | AL37: 142621280907873 | AM37: 2026-09-11 10:55 | AR37: No RCM – forward charge; IGST 18% charged by supplier. ITC eligible (check GSTR-2B). Payment term 15 days. | AS37: Sec 393(1) – fees for technical services (old 194J(a)), 2%. Confirm with CA. | AT37: 0.02
A38: 34 | B38: Pine Labs Limited\INV092609248716 10.09.26.pdf | C38: INV092609248716 | D38: 46275 | E38: =YEAR(D38) -> 2026 | F38: =TEXT(D38,"mmm") -> Sep | G38: Pine Labs Limited | H38: 09AACCP7457K1ZV | J38: Plutus PoS Service Fee – Aug-26 (line 2) | K38: 998319 | M38: 1 | N38: NOS | O38: 4200 | P38: 0 | Q38: =M38*O38-P38 -> 4200 | R38: 0.18 | S38: IGST | T38: =IF(S38="IGST",ROUND(Q38*R38,2),0) -> 756 | U38: =IF(S38="CGST+SGST",ROUND(Q38*R38/2,2),0) -> 0 | V38: =U38 -> 0 | W38: 0 | X38: =Q38+T38+U38+V38+W38 -> 4956 | Y38: =ROUND(Q38*AT38,0) -> 84 | Z38: =X38-Y38 -> 4872 | AD38: Uttar Pradesh (09) | AE38: 07AAFCN6567R1ZJ | AF38: Delhi (07) | AG38: 12477167 | AH38: 45217 | AK38: 839bd782fcfc91fa31e6f83f9b07b14947d83dfd1799675967bc0255960a2c1d | AL38: 142621280907873 | AM38: 2026-09-11 10:55 | AR38: No RCM – forward charge; IGST 18% charged by supplier. ITC eligible (check GSTR-2B). Payment term 15 days. | AS38: Sec 393(1) – fees for technical services (old 194J(a)), 2%. Confirm with CA. | AT38: 0.02
A39: 35 | B39: Pine Labs Limited\INV092609248716 10.09.26.pdf | C39: INV092609248716 | D39: 46275 | E39: =YEAR(D39) -> 2026 | F39: =TEXT(D39,"mmm") -> Sep | G39: Pine Labs Limited | H39: 09AACCP7457K1ZV | J39: Plutus PoS Service Fee – Aug-26 (line 3) | K39: 998319 | M39: 1 | N39: NOS | O39: 600 | P39: 0 | Q39: =M39*O39-P39 -> 600 | R39: 0.18 | S39: IGST | T39: =IF(S39="IGST",ROUND(Q39*R39,2),0) -> 108 | U39: =IF(S39="CGST+SGST",ROUND(Q39*R39/2,2),0) -> 0 | V39: =U39 -> 0 | W39: 0 | X39: =Q39+T39+U39+V39+W39 -> 708 | Y39: =ROUND(Q39*AT39,0) -> 12 | Z39: =X39-Y39 -> 696 | AD39: Uttar Pradesh (09) | AE39: 07AAFCN6567R1ZJ | AF39: Delhi (07) | AG39: 12477167 | AH39: 45217 | AK39: 839bd782fcfc91fa31e6f83f9b07b14947d83dfd1799675967bc0255960a2c1d | AL39: 142621280907873 | AM39: 2026-09-11 10:55 | AR39: No RCM – forward charge; IGST 18% charged by supplier. ITC eligible (check GSTR-2B). Payment term 15 days. | AS39: Sec 393(1) – fees for technical services (old 194J(a)), 2%. Confirm with CA. | AT39: 0.02
A40: 36 | B40: Pine Labs Limited\INV092609248716 10.09.26.pdf | C40: INV092609248716 | D40: 46275 | E40: =YEAR(D40) -> 2026 | F40: =TEXT(D40,"mmm") -> Sep | G40: Pine Labs Limited | H40: 09AACCP7457K1ZV | J40: Plutus PoS Service Fee – Aug-26 (line 4) | K40: 998319 | M40: 1 | N40: NOS | O40: 600 | P40: 0 | Q40: =M40*O40-P40 -> 600 | R40: 0.18 | S40: IGST | T40: =IF(S40="IGST",ROUND(Q40*R40,2),0) -> 108 | U40: =IF(S40="CGST+SGST",ROUND(Q40*R40/2,2),0) -> 0 | V40: =U40 -> 0 | W40: 0 | X40: =Q40+T40+U40+V40+W40 -> 708 | Y40: =ROUND(Q40*AT40,0) -> 12 | Z40: =X40-Y40 -> 696 | AD40: Uttar Pradesh (09) | AE40: 07AAFCN6567R1ZJ | AF40: Delhi (07) | AG40: 12477167 | AH40: 45217 | AK40: 839bd782fcfc91fa31e6f83f9b07b14947d83dfd1799675967bc0255960a2c1d | AL40: 142621280907873 | AM40: 2026-09-11 10:55 | AR40: No RCM – forward charge; IGST 18% charged by supplier. ITC eligible (check GSTR-2B). Payment term 15 days. | AS40: Sec 393(1) – fees for technical services (old 194J(a)), 2%. Confirm with CA. | AT40: 0.02
A41: 37 | B41: Pine Labs Limited\INV092609248716 10.09.26.pdf | C41: INV092609248716 | D41: 46275 | E41: =YEAR(D41) -> 2026 | F41: =TEXT(D41,"mmm") -> Sep | G41: Pine Labs Limited | H41: 09AACCP7457K1ZV | J41: Plutus PoS Service Fee – Aug-26 (line 5) | K41: 998319 | M41: 1 | N41: NOS | O41: 2700 | P41: 0 | Q41: =M41*O41-P41 -> 2700 | R41: 0.18 | S41: IGST | T41: =IF(S41="IGST",ROUND(Q41*R41,2),0) -> 486 | U41: =IF(S41="CGST+SGST",ROUND(Q41*R41/2,2),0) -> 0 | V41: =U41 -> 0 | W41: 0 | X41: =Q41+T41+U41+V41+W41 -> 3186 | Y41: =ROUND(Q41*AT41,0) -> 54 | Z41: =X41-Y41 -> 3132 | AD41: Uttar Pradesh (09) | AE41: 07AAFCN6567R1ZJ | AF41: Delhi (07) | AG41: 12477167 | AH41: 45217 | AK41: 839bd782fcfc91fa31e6f83f9b07b14947d83dfd1799675967bc0255960a2c1d | AL41: 142621280907873 | AM41: 2026-09-11 10:55 | AR41: No RCM – forward charge; IGST 18% charged by supplier. ITC eligible (check GSTR-2B). Payment term 15 days. | AS41: Sec 393(1) – fees for technical services (old 194J(a)), 2%. Confirm with CA. | AT41: 0.02
...

Sheet Emails Not Scanned
A1: Emails Not Scanned – invoice@nicobar.com
A2: Last Gmail scan: 01-10-2026 14:40 IST (window: 26-09-2026 21:59 IST to 01-10-2026 14:40 IST). Runs of 02-10-2026 10:41 IST, 03-10-2026 17:29 IST and 04-10-2026 09:13 IST could NOT scan Gmail (connector not attached) – window 01-10-2026 14:40 to 04-10-2026 09:13 IST still to be scanned. Emails below were not downloaded, or were scanned but their PDFs were not added to the register. The scheduled task retries "Not downloaded" emails each run.
A4: A. Not downloaded – PDFs NOT in the register (action needed)
A5: # | B5: Email Date (IST) | C5: From | D5: To | E5: Cc | F5: Subject | G5: Size (MB) | H5: Status | I5: Reason | J5: Action Needed | K5: Gmail Message ID | L5: Open in Gmail | M5: Last Attempt (IST)
A6: 1 | B6: 46289.48 | C6: rohitpundir@nicobar.com | D6: invoice@nicobar.com | F6: invoices | G6: 12.1 | H6: Not downloaded | I6: Download failed again on 01-10-2026 – the Gmail connection times out (session expired) on this very large email (~12.7 MB). It contains 12 PDFs: invoice_IN-2026-0408358, 2026-27194 - Nicobar Design Pvt Ltd, nico bar Sept, Niobar invoice, SHPL-PI-03-26-27, 2966091990_Nicobar_HVAC_20260801, 100107669 (4), Abode Inn- Invoice Jaipur, 2966091990_Nicobar_HVAC, Aug Sep 2026, LNKD_INVOICE_511294839131, maneet_invoice-nicobar. | J6: Save its PDFs into D:\Claude_Sales\Expenses (any subfolder) – the next run files them – or ask the sender to resend in smaller emails (under ~5 MB each). | K6: 1a0d201f04a25ddb | L6: Open email | M6: 46296.615
A7: 2 | B7: 46290.559 | C7: sanjaysharma@nicobar.com | D7: invoice@nicobar.com | E7: sachin@nicobar.com; shekharsingh@nicobar.com | F7: Invoices copy | G7: 13.8 | H7: Not downloaded | I7: Download failed again on 01-10-2026 – the Gmail connection times out (session expired) on this very large email (~14.5 MB). | J7: Save its PDFs into D:\Claude_Sales\Expenses, or ask the sender to resend in smaller emails. | K7: 1a0d7910bc5c3986 | L7: Open email | M7: 46296.615
A8: 3 | B8: 46289.683 | C8: prachisyal@nicobar.com | D8: invoice@nicobar.com | E8: sachin@nicobar.com | F8: scanned invoices | G8: 27.2 | H8: Not downloaded | I8: Too large to download (~28.6 MB) – emails of 12–14 MB still time out, so it was skipped again on 01-10-2026. | J8: Save its PDFs into D:\Claude_Sales\Expenses, or ask the sender to resend in smaller emails. | K8: 1a0d30cfb9b6e9da | L8: Open email | M8: 46296.615
A9: 4 | B9: 46289.728 | C9: prachisyal@nicobar.com | D9: invoice@nicobar.com | E9: sachin@nicobar.com | F9: Re: scanned invoices | G9: 18.6 | H9: Not downloaded | I9: Too large to download (~19.6 MB) – emails of 12–14 MB still time out, so it was skipped again on 01-10-2026. (The middle reply in this thread, 2.3 MB, WAS scanned: 12 DLF invoices + V Dine voucher added.) | J9: Save its PDFs into D:\Claude_Sales\Expenses, or ask the sender to resend in smaller emails. | K9: 1a0d348710f4c2a0 | L9: Open email | M9: 46296.615
A10: 5 | B10: — | C10: — (Gmail not read) | D10: invoice@nicobar.com | F10: Gmail not scanned – Gmail connector not attached to this scheduled task | H10: Not scanned | I10: Gmail not scanned on 02-10-2026, 03-10-2026 or 04-10-2026 – no Gmail tools were available to these runs (connector not attached to the scheduled task). Scan window NOT covered: 01-10-2026 14:40 IST to 04-10-2026 09:13 IST. The watermark was not advanced, so the next successful run will search this window. | J10: Re-attach the Gmail connector (with access to invoice@nicobar.com) to the scheduled task "Auto-add new invoices to Expense Register". | K10: — | M10: 2026-10-04 09:13
A12: B. Scanned – PDFs not added to the register (for information)
A13: # | B13: Email Date (IST) | C13: From | D13: To | E13: Cc | F13: Subject | G13: Size (MB) | H13: Status | I13: Reason | J13: Action Needed | K13: Gmail Message ID | L13: Open in Gmail | M13: Last Attempt (IST)
A14: 6 | B14: 46289.484 | C14: rohitpundir@nicobar.com | D14: invoice@nicobar.com | F14: Fwd: Electricity Bill | G14: 0.7 | H14: Scanned – not added | I14: Not billed to Nicobar: PSPCL electricity bill no. 50823959885 (a/c 3009140989) is in the name of Mr. Inderjeet Singh Dhillon; payable ₹24,947, due 21-Sep-2026. | J14: Pay/claim as landlord reimbursement if applicable; ask landlord for a GST invoice if needed. | K14: 1a0d206d9ab92844 | L14: Open email | M14: 46291.917
A15: 7 | B15: 46289.484 | C15: rohitpundir@nicobar.com | D15: invoice@nicobar.com | F15: Fwd: JCN Electricity Bill Payment Request for Aug-2026 | G15: 0.7 | H15: Scanned – not added | I15: Not billed to Nicobar: two Jaipur (JVVNL) electricity bills in the names of Rajeshwar Singh (₹35,646) and Narendra Kumari (₹22,459), due 22-Sep-2026. | J15: Same as above – landlord/individual bills. | K15: 1a0d206fd4b41ccc | L15: Open email | M15: 46291.917
A16: 8 | B16: 46289.484 | C16: rohitpundir@nicobar.com | D16: invoice@nicobar.com | F16: Fwd: PFA | G16: 0.4 | H16: Scanned – duplicate | I16: All 9 PDFs (Anthropic E87270F6-0001 to -0009) are already in the register (S.No. 23–31). | J16: None. | K16: 1a0d20671601042b | L16: Open email | M16: 46291.917
A17: 9 | B17: 46289.483 | C17: rohitpundir@nicobar.com | D17: invoice@nicobar.com | F17: Fwd: DPS BILL NMN | G17: 0.2 | H17: Scanned – duplicate | I17: DPS Telecom 09-UPTIN26003027 is already in the register (S.No. 14). | J17: None. | K17: 1a0d205577740520 | L17: Open email | M17: 46291.917
A18: 10 | B18: 46289.484 | C18: rohitpundir@nicobar.com | D18: invoice@nicobar.com | F18: Fwd: Invoices | G18: 0.7 | H18: Scanned – duplicate | I18: All 3 Vraj Commercial invoices (CH/0562, EL-DG/0545, Rent/0613) are already in the register (S.No. 15–22). | J18: None. | K18: 1a0d2069e10849b4 | L18: Open email | M18: 46291.917
A19: 11 | B19: 46289.72 | C19: himanshu@nicobar.com | D19: invoice@nicobar.com | F19: Fwd: FW: DTDC Freight Invoice For The Month Of Aug-26 (NICOBAR DESIGN PRIVATE LIMITED) | G19: 1.2 | H19: Scanned – duplicate | I19: Second copy of the same 14 DTDC PDFs; the first email in the thread was added. | J19: None. | K19: 1a0d33e26521b364 | L19: Open email | M19: 46291.917
A20: 12 | B20: 46290.459 | C20: rohitpundir@nicobar.com | D20: invoice@nicobar.com | F20: Fwd: Payout | Surbhi Sethi | Sept | G20: 2.6 | H20: Scanned – partly added | I20: Invoice 013/2026-27 was added. The other 2 PDFs (GST registration certificate, cancelled cheque + PAN) are supporting documents, not invoices. | J20: None. | K20: 1a0d70bed2fc365a | L20: Open email | M20: 46291.917
A21: 13 | B21: 46289.721 | C21: himanshu@nicobar.com | D21: invoice@nicobar.com | F21: Fwd: FW: Blue Dart Invoice for month of AUGUST 2026 - FAR322055 | G21: 3.4 | H21: Scanned – partly added | I21: 7 invoices were added. The "CovReport" PDF is a statement/cover summary (total ₹58,559.18), not an invoice. | J21: None. | K21: 1a0d33e6fd2816a4 | L21: Open email | M21: 46291.917
A22: 14 | B22: 46296.609 | C22: sachin@nicobar.com (fwd from Mohit Jaiswal) | D22: invoice@nicobar.com | F22: FW: Monthly closing Sep26 | G22: 0.13 | H22: Scanned – not added | I22: Not billed to Nicobar: IPinfo Inc. invoice 3MNDSIX0-0003 dated 06-06-2026 (US$481.40) is billed to "Shashi Kapoor" (an individual), not Nicobar Design Pvt Ltd. | J22: Ask IPinfo to reissue the invoice in Nicobar Design Pvt Ltd name (with GSTIN) if it is to be booked; otherwise save it into D:\Claude_Sales\Expenses and confirm. | K22: 1a0f6b74723eef83 | L22: Open email | M22: 46296.615
A23: 15 | B23: 46296.609 | C23: sachin@nicobar.com (fwd from Archana Roy) | D23: invoice@nicobar.com | F23: FW: NICOBAR DEAL @ JUHU BROKERAGE FEE CONFIRMATION | G23: 0.27 | H23: Scanned – duplicate | I23: Earlier copy of Cushman & Wakefield invoice MH-2026-09-2376 (Lower Parel bill-to address); same invoice no. and IRN as the revised invoice that WAS added from the 01-10-2026 email. | J23: None. | K23: 1a0f6b798b0b622f | L23: Open email | M23: 46296.615
A24: 16 | B24: 46296.607 | C24: sachin@nicobar.com (fwd from MKR APP) | D24: invoice@nicobar.com | F24: FW: Request for Account Statement – April 2026 to Date | G24: 0.38 | H24: Scanned – not added | I24: GL_26-27.pdf is an account statement, not an invoice. MKR says invoices MKR/26-27/8 (15-07-2026) and MKR/26-27/12 (15-09-2026) are not in Nicobar records – neither invoice PDF was attached. | J24: Ask MKR APP (P) Ltd for copies of MKR/26-27/8 and /12 and save them into D:\Claude_Sales\Expenses. | K24: 1a0f6b4c4a7b2435 | L24: Open email | M24: 46296.615
A25: 17 | B25: 46296.609 | C25: sachin@nicobar.com (fwd from Niva's Designs) | D25: invoice@nicobar.com | F25: FW: RE: NIVAS DESIGNS_Outstanding Payments as on 10-06-2026 | G25: 2.1 | H25: Scanned – partly added | I25: Invoice ND/26-27/043A (Haryana, ₹35,539) was added. ND/26-27/043 dated 29-07-2026 (Delhi, IGST) was not added because credit note ND/26-27/CN3 cancels it (credit notes are not entered). | J25: None. | K25: 1a0f6b78bc5359c3 | L25: Open email | M25: 46296.615
